2021-05-27 04:19:42,002 INFO    MainThread:17656 [internal.py:wandb_internal():91] W&B internal server running at pid: 17656, started at: 2021-05-27 04:19:42.002400
2021-05-27 04:19:42,006 DEBUG   HandlerThread:17656 [handler.py:handle_request():121] handle_request: check_version
2021-05-27 04:19:42,007 DEBUG   SenderThread:17656 [sender.py:send():176] send: header
2021-05-27 04:19:42,007 DEBUG   SenderThread:17656 [sender.py:send_request():186] send_request: check_version
2021-05-27 04:19:42,007 INFO    WriterThread:17656 [datastore.py:open_for_write():77] open: /opt/ml/code/wandb/run-20210527_041941-3ttglkon/run-3ttglkon.wandb
2021-05-27 04:19:42,599 DEBUG   SenderThread:17656 [sender.py:send():176] send: run
2021-05-27 04:19:42,607 DEBUG   SenderThread:17656 [git.py:repo():33] git repository is invalid
2021-05-27 04:19:42,832 INFO    SenderThread:17656 [dir_watcher.py:__init__():168] watching files in: /opt/ml/code/wandb/run-20210527_041941-3ttglkon/files
2021-05-27 04:19:42,833 INFO    SenderThread:17656 [sender.py:_start_run_threads():699] run started: 3ttglkon with start time 1622089181
2021-05-27 04:19:42,833 DEBUG   SenderThread:17656 [sender.py:send():176] send: summary
2021-05-27 04:19:42,833 INFO    SenderThread:17656 [sender.py:_save_file():821] saving file wandb-summary.json with policy end
2021-05-27 04:19:42,835 DEBUG   HandlerThread:17656 [handler.py:handle_request():121] handle_request: run_start
2021-05-27 04:19:42,840 DEBUG   HandlerThread:17656 [meta.py:__init__():39] meta init
2021-05-27 04:19:42,840 DEBUG   HandlerThread:17656 [meta.py:__init__():53] meta init done
2021-05-27 04:19:42,840 DEBUG   HandlerThread:17656 [meta.py:probe():210] probe
2021-05-27 04:19:42,846 DEBUG   HandlerThread:17656 [git.py:repo():33] git repository is invalid
2021-05-27 04:19:42,846 DEBUG   HandlerThread:17656 [meta.py:_save_pip():57] save pip
2021-05-27 04:19:42,847 DEBUG   HandlerThread:17656 [meta.py:_save_pip():71] save pip done
2021-05-27 04:19:42,847 DEBUG   HandlerThread:17656 [meta.py:_save_conda():78] save conda
2021-05-27 04:19:43,834 INFO    Thread-8  :17656 [dir_watcher.py:_on_file_created():216] file/dir created: /opt/ml/code/wandb/run-20210527_041941-3ttglkon/files/conda-environment.yaml
2021-05-27 04:19:43,835 INFO    Thread-8  :17656 [dir_watcher.py:_on_file_created():216] file/dir created: /opt/ml/code/wandb/run-20210527_041941-3ttglkon/files/wandb-summary.json
2021-05-27 04:19:43,835 INFO    Thread-8  :17656 [dir_watcher.py:_on_file_created():216] file/dir created: /opt/ml/code/wandb/run-20210527_041941-3ttglkon/files/requirements.txt
2021-05-27 04:19:45,514 DEBUG   HandlerThread:17656 [meta.py:_save_conda():86] save conda done
2021-05-27 04:19:45,514 DEBUG   HandlerThread:17656 [meta.py:probe():252] probe done
2021-05-27 04:19:45,518 DEBUG   SenderThread:17656 [sender.py:send():176] send: files
2021-05-27 04:19:45,519 INFO    SenderThread:17656 [sender.py:_save_file():821] saving file wandb-metadata.json with policy now
2021-05-27 04:19:45,523 DEBUG   HandlerThread:17656 [handler.py:handle_request():121] handle_request: stop_status
2021-05-27 04:19:45,523 DEBUG   SenderThread:17656 [sender.py:send_request():186] send_request: stop_status
2021-05-27 04:19:45,833 INFO    Thread-8  :17656 [dir_watcher.py:_on_file_created():216] file/dir created: /opt/ml/code/wandb/run-20210527_041941-3ttglkon/files/output.log
2021-05-27 04:19:45,834 INFO    Thread-8  :17656 [dir_watcher.py:_on_file_created():216] file/dir created: /opt/ml/code/wandb/run-20210527_041941-3ttglkon/files/wandb-metadata.json
2021-05-27 04:19:46,164 INFO    Thread-11 :17656 [upload_job.py:push():133] Uploaded file /tmp/tmp4czwaty1wandb/3uar0oos-wandb-metadata.json
2021-05-27 04:19:53,710 ERROR   FileStreamThread:17656 [file_stream.py:_thread_except_body():286] generic exception in filestream thread
Traceback (most recent call last):
  File "/opt/conda/lib/python3.7/site-packages/wandb/sdk/internal/file_stream.py", line 282, in _thread_except_body
    self._thread_body()
  File "/opt/conda/lib/python3.7/site-packages/wandb/sdk/internal/file_stream.py", line 260, in _thread_body
    self._send(ready_chunks)
  File "/opt/conda/lib/python3.7/site-packages/wandb/sdk/internal/file_stream.py", line 327, in _send
    retry_callback=self._api.retry_callback,
  File "/opt/conda/lib/python3.7/site-packages/wandb/sdk/internal/file_stream.py", line 295, in _handle_response
    raise response
  File "/opt/conda/lib/python3.7/site-packages/wandb/sdk/internal/file_stream.py", line 382, in request_with_retry
    response.raise_for_status()
  File "/opt/conda/lib/python3.7/site-packages/requests/models.py", line 941, in raise_for_status
    raise HTTPError(http_error_msg, response=self)
requests.exceptions.HTTPError: 404 Client Error: Not Found for url: https://api.wandb.ai/files/ganta/OCR/3ttglkon/file_stream
2021-05-27 04:19:59,178 DEBUG   HandlerThread:17656 [handler.py:handle_request():121] handle_request: poll_exit
2021-05-27 04:19:59,178 DEBUG   SenderThread:17656 [sender.py:send():176] send: telemetry
2021-05-27 04:19:59,178 DEBUG   SenderThread:17656 [sender.py:send():176] send: exit
2021-05-27 04:19:59,178 INFO    SenderThread:17656 [sender.py:send_exit():281] handling exit code: 1
2021-05-27 04:19:59,179 INFO    SenderThread:17656 [sender.py:send_exit():289] send defer
2021-05-27 04:19:59,179 DEBUG   SenderThread:17656 [sender.py:send_request():186] send_request: poll_exit
2021-05-27 04:19:59,179 DEBUG   HandlerThread:17656 [handler.py:handle_request():121] handle_request: defer
2021-05-27 04:19:59,179 INFO    HandlerThread:17656 [handler.py:handle_request_defer():138] handle defer: 0
2021-05-27 04:19:59,179 DEBUG   SenderThread:17656 [sender.py:send_request():186] send_request: defer
2021-05-27 04:19:59,180 INFO    SenderThread:17656 [sender.py:send_request_defer():298] handle sender defer: 0
2021-05-27 04:19:59,180 INFO    SenderThread:17656 [sender.py:send_request_defer():336] send defer: 1
2021-05-27 04:19:59,180 DEBUG   HandlerThread:17656 [handler.py:handle_request():121] handle_request: defer
2021-05-27 04:19:59,180 INFO    HandlerThread:17656 [handler.py:handle_request_defer():138] handle defer: 1
2021-05-27 04:19:59,234 DEBUG   SenderThread:17656 [sender.py:send_request():186] send_request: defer
2021-05-27 04:19:59,235 INFO    SenderThread:17656 [sender.py:send_request_defer():298] handle sender defer: 1
2021-05-27 04:19:59,235 INFO    SenderThread:17656 [sender.py:send_request_defer():336] send defer: 2
2021-05-27 04:19:59,235 DEBUG   SenderThread:17656 [sender.py:send():176] send: stats
2021-05-27 04:19:59,235 DEBUG   HandlerThread:17656 [handler.py:handle_request():121] handle_request: defer
2021-05-27 04:19:59,235 INFO    HandlerThread:17656 [handler.py:handle_request_defer():138] handle defer: 2
2021-05-27 04:19:59,236 DEBUG   SenderThread:17656 [sender.py:send_request():186] send_request: defer
2021-05-27 04:19:59,236 INFO    SenderThread:17656 [sender.py:send_request_defer():298] handle sender defer: 2
2021-05-27 04:19:59,236 INFO    SenderThread:17656 [sender.py:send_request_defer():336] send defer: 3
2021-05-27 04:19:59,236 DEBUG   HandlerThread:17656 [handler.py:handle_request():121] handle_request: defer
2021-05-27 04:19:59,236 INFO    HandlerThread:17656 [handler.py:handle_request_defer():138] handle defer: 3
2021-05-27 04:19:59,236 DEBUG   SenderThread:17656 [sender.py:send():176] send: summary
2021-05-27 04:19:59,236 INFO    SenderThread:17656 [sender.py:_save_file():821] saving file wandb-summary.json with policy end
2021-05-27 04:19:59,237 DEBUG   SenderThread:17656 [sender.py:send_request():186] send_request: defer
2021-05-27 04:19:59,237 INFO    SenderThread:17656 [sender.py:send_request_defer():298] handle sender defer: 3
2021-05-27 04:19:59,237 INFO    SenderThread:17656 [sender.py:send_request_defer():336] send defer: 4
2021-05-27 04:19:59,237 DEBUG   HandlerThread:17656 [handler.py:handle_request():121] handle_request: defer
2021-05-27 04:19:59,237 INFO    HandlerThread:17656 [handler.py:handle_request_defer():138] handle defer: 4
2021-05-27 04:19:59,237 DEBUG   SenderThread:17656 [sender.py:send_request():186] send_request: defer
2021-05-27 04:19:59,237 INFO    SenderThread:17656 [sender.py:send_request_defer():298] handle sender defer: 4
2021-05-27 04:19:59,282 DEBUG   HandlerThread:17656 [handler.py:handle_request():121] handle_request: poll_exit
2021-05-27 04:19:59,428 ERROR   SenderThread:17656 [internal_api.py:execute():130] 409 response executing GraphQL.
2021-05-27 04:19:59,428 ERROR   SenderThread:17656 [internal_api.py:execute():131] {"errors":[{"message":"Error 1062: Duplicate entry '324675-3ttglkon' for key 'PRIMARY'","path":["upsertBucket"]}],"data":{"upsertBucket":null}}
2021-05-27 04:19:59,838 INFO    Thread-8  :17656 [dir_watcher.py:_on_file_modified():229] file/dir modified: /opt/ml/code/wandb/run-20210527_041941-3ttglkon/files/output.log
2021-05-27 04:19:59,838 INFO    Thread-8  :17656 [dir_watcher.py:_on_file_modified():229] file/dir modified: /opt/ml/code/wandb/run-20210527_041941-3ttglkon/files/wandb-summary.json
2021-05-27 04:20:00,736 ERROR   SenderThread:17656 [internal_api.py:execute():130] 409 response executing GraphQL.
2021-05-27 04:20:00,737 ERROR   SenderThread:17656 [internal_api.py:execute():131] {"errors":[{"message":"Error 1062: Duplicate entry '324675-3ttglkon' for key 'PRIMARY'","path":["upsertBucket"]}],"data":{"upsertBucket":null}}
2021-05-27 04:20:03,293 ERROR   SenderThread:17656 [internal_api.py:execute():130] 409 response executing GraphQL.
2021-05-27 04:20:03,293 ERROR   SenderThread:17656 [internal_api.py:execute():131] {"errors":[{"message":"Error 1062: Duplicate entry '324675-3ttglkon' for key 'PRIMARY'","path":["upsertBucket"]}],"data":{"upsertBucket":null}}
2021-05-27 04:20:03,293 ERROR   SenderThread:17656 [retry.py:__call__():126] Retry attempt failed:
Traceback (most recent call last):
  File "/opt/conda/lib/python3.7/site-packages/wandb/sdk/lib/retry.py", line 102, in __call__
    result = self._call_fn(*args, **kwargs)
  File "/opt/conda/lib/python3.7/site-packages/wandb/sdk/internal/internal_api.py", line 133, in execute
    six.reraise(*sys.exc_info())
  File "/opt/conda/lib/python3.7/site-packages/six.py", line 703, in reraise
    raise value
  File "/opt/conda/lib/python3.7/site-packages/wandb/sdk/internal/internal_api.py", line 127, in execute
    return self.client.execute(*args, **kwargs)
  File "/opt/conda/lib/python3.7/site-packages/wandb/vendor/gql-0.2.0/gql/client.py", line 52, in execute
    result = self._get_result(document, *args, **kwargs)
  File "/opt/conda/lib/python3.7/site-packages/wandb/vendor/gql-0.2.0/gql/client.py", line 60, in _get_result
    return self.transport.execute(document, *args, **kwargs)
  File "/opt/conda/lib/python3.7/site-packages/wandb/vendor/gql-0.2.0/gql/transport/requests.py", line 39, in execute
    request.raise_for_status()
  File "/opt/conda/lib/python3.7/site-packages/requests/models.py", line 941, in raise_for_status
    raise HTTPError(http_error_msg, response=self)
requests.exceptions.HTTPError: 409 Client Error: Conflict for url: https://api.wandb.ai/graphql
